Workbook
Name NativeTimeline_Date: #N/A
Name Slicer_City: #N/A
Name Slicer_City1: #N/A
Name Slicer_Customers: #N/A
Name Slicer_Customers1: #N/A
Name Slicer_Customers2: #N/A
Name Timeline_Date: #N/A

Sheet Sheet2
A3: Sum of Total sales | B3: Column Labels
B4: 0.21810314 | C4: 0.25615224 | D4: 0.26934112 | E4: 0.35719259 | F4: 0.37435009 | G4: 0.6059847 | H4: 1 | I4: Grand Total
B5: berlin | C5: dubi | D5: istanbul | E5: egypt | F5: istanbul | G5: london | H5: london
A6: Row Labels | B6: rania | C6: lama | D6: dania | E6: mert | F6: mazen | G6: fadel | H6: lana
A7: Good Customer | B7: 188.5 | C7: 173.1 | E7: 179.55 | F7: 120.96 | I7: 662.11
A8: Normal Customer | D8: 54.45 | G8: 89.51 | H8: 58.2 | I8: 202.16
A9: Grand Total | B9: 188.5 | C9: 173.1 | D9: 54.45 | E9: 179.55 | F9: 120.96 | G9: 89.51 | H9: 58.2 | I9: 864.27

Sheet dania
A1: Customers | B1: (All)
A3: Row Labels | B3: Sum of Net profit
A4: 45658 | B4: 95
A5: istanbul | B5: 95
A6: 45659 | B6: 49
A7: berlin | B7: 49
A8: 45660 | B8: 39.2
A9: london | B9: 39.2
A10: 45661 | B10: 139.5
A11: dubi | B11: 139.5
A12: 45662 | B12: 54.45
A13: istanbul | B13: 54.45
A14: 45663 | B14: 44.55
A15: egybt | B15: 44.55
A16: 45664 | B16: 19.76
A17: istanbul | B17: 19.76
A18: 45665 | B18: 19.76
A19: london | B19: 19.76
A20: 45666 | B20: 139.5
A21: berlin | B21: 139.5
A22: 45667 | B22: 58.2
A23: london | B23: 58.2
A24: 45668 | B24: 135
A25: egypt | B25: 135
A26: 45669 | B26: 33.6
A27: dubi | B27: 33.6
A28: 45670 | B28: 69.75
A29: london | B29: 69.75
A30: 45671 | B30: 101.2
A31: istanbul | B31: 101.2
A32: Grand Total | B32: 998.47

Sheet fadel
A1: Customers | B1: (All)
A3: Row Labels | B3: Sum of Net profit
A4: 45658 | B4: 95
A5: 45659 | B5: 49
A6: 45660 | B6: 39.2
A7: 45661 | B7: 139.5
A8: 45662 | B8: 54.45
A9: 45663 | B9: 44.55
A10: 45664 | B10: 19.76
A11: 45665 | B11: 19.76
A12: 45666 | B12: 139.5
A13: 45667 | B13: 58.2
A14: 45668 | B14: 135
A15: 45669 | B15: 33.6
... A17: 45671 | B17: 101.2
A18: Grand Total | B18: 998.47

Sheet lama
A1: Customers | B1: (All)
A3: Row Labels | B3: Sum of Net profit
A4: 45658 | B4: 95
A5: 45659 | B5: 49
A6: 45660 | B6: 39.2
A7: 45661 | B7: 139.5
A8: 45662 | B8: 54.45
A9: 45663 | B9: 44.55
A10: 45664 | B10: 19.76
A11: 45665 | B11: 19.76
A12: 45666 | B12: 139.5
A13: 45667 | B13: 58.2
A14: 45668 | B14: 135
A15: 45669 | B15: 33.6
... A17: 45671 | B17: 101.2
A18: Grand Total | B18: 998.47

Sheet lana
A1: Customers | B1: (All)
A3: Row Labels | B3: Sum of Net profit
A4: 45658 | B4: 95
A5: 45659 | B5: 49
A6: 45660 | B6: 39.2
A7: 45661 | B7: 139.5
A8: 45662 | B8: 54.45
A9: 45663 | B9: 44.55
A10: 45664 | B10: 19.76
A11: 45665 | B11: 19.76
A12: 45666 | B12: 139.5
A13: 45667 | B13: 58.2
A14: 45668 | B14: 135
A15: 45669 | B15: 33.6
... A17: 45671 | B17: 101.2
A18: Grand Total | B18: 998.47

Sheet mazen
A1: Customers | B1: (All)
A3: Row Labels | B3: Sum of Net profit
A4: 45658 | B4: 95
A5: 45659 | B5: 49
A6: 45660 | B6: 39.2
A7: 45661 | B7: 139.5
A8: 45662 | B8: 54.45
A9: 45663 | B9: 44.55
A10: 45664 | B10: 19.76
A11: 45665 | B11: 19.76
A12: 45666 | B12: 139.5
A13: 45667 | B13: 58.2
A14: 45668 | B14: 135
A15: 45669 | B15: 33.6
... A17: 45671 | B17: 101.2
A18: Grand Total | B18: 998.47

Sheet mert
A1: Customers | B1: (All)
A3: Row Labels | B3: Sum of Net profit
A4: 45658 | B4: 95
A5: 45659 | B5: 49
A6: 45660 | B6: 39.2
A7: 45661 | B7: 139.5
A8: 45662 | B8: 54.45
A9: 45663 | B9: 44.55
A10: 45664 | B10: 19.76
A11: 45665 | B11: 19.76
A12: 45666 | B12: 139.5
A13: 45667 | B13: 58.2
A14: 45668 | B14: 135
A15: 45669 | B15: 33.6
... A17: 45671 | B17: 101.2
A18: Grand Total | B18: 998.47

Sheet rania
A1: Customers | B1: (All)
A3: Row Labels | B3: Sum of Net profit
A4: 45658 | B4: 95
A5: 45659 | B5: 49
A6: 45660 | B6: 39.2
A7: 45661 | B7: 139.5
A8: 45662 | B8: 54.45
A9: 45663 | B9: 44.55
A10: 45664 | B10: 19.76
A11: 45665 | B11: 19.76
A12: 45666 | B12: 139.5
A13: 45667 | B13: 58.2
A14: 45668 | B14: 135
A15: 45669 | B15: 33.6
... A17: 45671 | B17: 101.2
A18: Grand Total | B18: 998.47

Sheet Detail1
A1: Details for Sum of Net profit - Date: 1/7/2025, Customers: dania (+)
A3: Customers | B3: Type of sale | C3: The price | D3: Date | E3: Net profit | F3: City | G3: the tax | H3: collection date | I3: Number of days remaining | J3: Type of the jewelry
A4: mazen | B4: sunglasses | C4: 20 | D4: 45664 | E4: 19.76 | F4: istanbul | G4: 0.012 | H4: 45747 | I4: -298 | J4: Gold

Sheet Detail3
A1: Details for Sum of Net profit - Customers: dania (+)
A3: Customers | B3: Type of sale | C3: The price | D3: Date | E3: Net profit | F3: City | G3: the tax | H3: collection date | I3: Number of days remaining | J3: Type of the jewelry
A4: dania | B4: necklace | C4: 100 | D4: 45658 | E4: 95 | F4: istanbul | G4: 0.05 | H4: 45747 | I4: -298 | J4: Gold
A5: rania | B5: ring | C5: 50 | D5: 45659 | E5: 49 | F5: berlin | G5: 0.02 | H5: 45747 | I5: -298 | J5: Diamond
A6: lana | B6: wristband | C6: 40 | D6: 45660 | E6: 39.2 | F6: london | G6: 0.02 | H6: 45747 | I6: -298 | J6: Gold
A7: lama | B7: ring | C7: 150 | D7: 45661 | E7: 139.5 | F7: dubi | G7: 0.07 | H7: 45747 | I7: -298 | J7: Diamond
A8: dania | B8: sunglasses | C8: 55 | D8: 45662 | E8: 54.45 | F8: istanbul | G8: 0.01 | H8: 45747 | I8: -298 | J8: Gold
A9: mert | B9: necklace | C9: 45 | D9: 45663 | E9: 44.55 | F9: egybt | G9: 0.01 | H9: 45747 | I9: -298 | J9: Gold
A10: mazen | B10: sunglasses | C10: 20 | D10: 45664 | E10: 19.76 | F10: istanbul | G10: 0.012 | H10: 45747 | I10: -298 | J10: Gold
A11: fadel | B11: sunglasses | C11: 20 | D11: 45665 | E11: 19.76 | F11: london | G11: 0.012 | H11: 45747 | I11: -298 | J11: Gold
A12: rania | B12: necklace | C12: 150 | D12: 45666 | E12: 139.5 | F12: berlin | G12: 0.07 | H12: 45747 | I12: -298 | J12: Diamond
A13: lana | B13: wristband | C13: 60 | D13: 45667 | E13: 58.2 | F13: london | G13: 0.03 | H13: 45747 | I13: -298 | J13: Gold
A14: mert | B14: wristband | C14: 150 | D14: 45668 | E14: 135 | F14: egypt | G14: 0.1 | H14: 45747 | I14: -298 | J14: Gold
A15: lama | B15: ring | C15: 35 | D15: 45669 | E15: 33.6 | F15: dubi | G15: 0.04 | H15: 45747 | I15: -298 | J15: Diamond
... A17: mazen | B17: necklace | C17: 110 | D17: 45671 | E17: 101.2 | F17: istanbul | G17: 0.08 | H17: 45747 | I17: -298 | J17: Diamond

Sheet Detail2
A1: Details for Sum of Net profit - Type of sale: necklace, Customers: dania (+)
A3: Customers | B3: Type of sale | C3: The price | D3: Date | E3: Net profit | F3: City | G3: the tax | H3: collection date | I3: Number of days remaining | J3: Type of the jewelry
A4: dania | B4: necklace | C4: 100 | D4: 45658 | E4: 95 | F4: istanbul | G4: 0.05 | H4: 45747 | I4: -298 | J4: Gold
A5: mert | B5: necklace | C5: 45 | D5: 45663 | E5: 44.55 | F5: egybt | G5: 0.01 | H5: 45747 | I5: -298 | J5: Gold
A6: rania | B6: necklace | C6: 150 | D6: 45666 | E6: 139.5 | F6: berlin | G6: 0.07 | H6: 45747 | I6: -298 | J6: Diamond
A7: fadel | B7: necklace | C7: 75 | D7: 45670 | E7: 69.75 | F7: london | G7: 0.07 | H7: 45747 | I7: -298 | J7: Diamond
A8: mazen | B8: necklace | C8: 110 | D8: 45671 | E8: 101.2 | F8: istanbul | G8: 0.08 | H8: 45747 | I8: -298 | J8: Diamond

Sheet Detail4
A1: Details for Sum of Net profit - Date: 1/1/2025, Customers: dania (+)
A3: Customers | B3: Type of sale | C3: The price | D3: Date | E3: Net profit | F3: City | G3: the tax | H3: collection date | I3: Number of days remaining | J3: Type of the jewelry
A4: dania | B4: necklace | C4: 100 | D4: 45658 | E4: 95 | F4: istanbul | G4: 0.05 | H4: 45747 | I4: -298 | J4: Gold

Sheet Sheet3
A2: Customers | B2: (All)
B4: Column Labels
A5: Row Labels | B5: High customer | C5: Low customer | D5: Grand Total
A6: Sum of HandMade
A7: 45658 | B7: 1.9 | C7: 0 | D7: 1.9
A8: 45659 | B8: 0.98 | C8: 0 | D8: 0.98
A9: 45660 | B9: 0 | C9: 0.784 | D9: 0.784
A10: 45661 | B10: 2.79 | C10: 0 | D10: 2.79
A11: 45662 | B11: 1.089 | C11: 0 | D11: 1.089
A12: 45663 | B12: 0.891 | C12: 0 | D12: 0.891
A13: 45664 | B13: 0 | C13: 0.3952 | D13: 0.3952
A14: 45665 | B14: 0 | C14: 0.3952 | D14: 0.3952
A15: 45666 | B15: 2.79 | C15: 0 | D15: 2.79
A16: 45667 | B16: 0 | C16: 1.164 | D16: 1.164
A17: 45668 | B17: 2.7 | C17: 0 | D17: 2.7
A18: 45669 | B18: 0.672 | C18: 0 | D18: 0.672
... A20: 45671 | B20: 0 | C20: 2.024 | D20: 2.024
A21: Sum of Net profit2
A22: 45658 | B22: 95 | D22: 95
A23: 45659 | B23: 49 | D23: 49
A24: 45660 | C24: 39.2 | D24: 39.2
A25: 45661 | B25: 139.5 | D25: 139.5
A26: 45662 | B26: 54.45 | D26: 54.45
A27: 45663 | B27: 44.55 | D27: 44.55
A28: 45664 | C28: 19.76 | D28: 19.76
A29: 45665 | C29: 19.76 | D29: 19.76
A30: 45666 | B30: 139.5 | D30: 139.5
A31: 45667 | C31: 58.2 | D31: 58.2
A32: 45668 | B32: 135 | D32: 135
A33: 45669 | B33: 33.6 | D33: 33.6
A34: 45670 | C34: 69.75 | D34: 69.75
A35: 45671 | C35: 101.2 | D35: 101.2
A36: Sum of Net profit
A37: 45658 | B37: 95 | D37: 95
A38: 45659 | B38: 49 | D38: 49
A39: 45660 | C39: 39.2 | D39: 39.2
A40: 45661 | B40: 139.5 | D40: 139.5
A41: 45662 | B41: 54.45 | D41: 54.45
A42: 45663 | B42: 44.55 | D42: 44.55
A43: 45664 | C43: 19.76 | D43: 19.76
...

Sheet Sheet1
B2: Customers Names | S2: Customer statistics
B5: Customers | C5: Type of sale | D5: The price | E5: Date | F5: Net profit | G5: City | H5: the tax | I5: collection date | J5: Number of days remaining | K5: Type of the jewelry | M5: Customer | N5: Net profit | O5: Type of sale | P5: Type of the jewelry | S5: Total sales | T5: Customers | U5: Type of customer | V5: percentage of sales | W5: City
B6: dania | C6: necklace | D6: 100 | E6: 45658 | F6: =D6-(D6*H6) -> 95 | G6: istanbul | H6: 0.05 | I6: =EOMONTH(MainTable[[#This Row],[Date]],2) -> 45747 | J6: =MainTable[[#This Row],[collection date]]-TODAY() -> -307 | K6: Gold | M6: dania | N6: =INDEX(MainTable[Net profit],MATCH($M$7,MainTable[[Customers]:[Customers]],0),MATCH(N4,MainTable[[#Headers],[Net profit]])) -> #N/A | O6: =INDEX(MainTable[City],MATCH($M$6,MainTable[[Customers]:[Customers]],0),MATCH(O5,MainTable[[#Headers],[City]])) -> istanbul | P6: =INDEX(MainTable[the tax],MATCH($M$6,MainTable[[Customers]:[Customers]],0),MATCH(P5,MainTable[[#Headers],[the tax]])) -> 0.05 | S6: =SUMIFS(F6:F19,B6:B19,T6,C6:C19,"necklace")+SUMIFS(F6:F19,B6:B19,T6,C6:C19,"ring")+SUMIFS(F6:F19,B6:B19,T6,C6:C19,"wristband")+SUMIFS(F6:F19,B6:B19,T6,C6:C19,"sunglasses") -> 188.5 | T6: rania | U6: =IF(S6>100,"Good Customer","Normal Customer") -> Good Customer | V6: =S6/SUM(S6:S12) -> 0.21810314 | W6: =VLOOKUP(T6, database!$A$2:$B$8,2, FALSE) -> berlin
B7: rania | C7: ring | D7: 50 | E7: 45659 | F7: =D7-(D7*H7) -> 49 | G7: berlin | H7: 0.02 | I7: =EOMONTH(MainTable[[#This Row],[Date]],2) -> 45747 | J7: =MainTable[[#This Row],[collection date]]-TODAY() -> -307 | K7: Diamond | M7: rania | N7: =INDEX(MainTable[Net profit],MATCH($M$7,MainTable[[Customers]:[Customers]],0),MATCH(N5,MainTable[[#Headers],[Net profit]])) -> 49 | O7: =INDEX(MainTable[City],MATCH($M$7,MainTable[[Customers]:[Customers]],0),MATCH(O6,MainTable[[#Headers],[City]])) -> berlin | P7: =INDEX(MainTable[the tax],MATCH($M$7,MainTable[[Customers]:[Customers]],0),MATCH(P5,MainTable[[#Headers],[the tax]])) -> 0.02 | S7: =SUMIFS(F7:F20,B7:B20,T7,C7:C20,"necklace")+SUMIFS(F7:F20,B7:B20,T7,C7:C20,"ring")+SUMIFS(F7:F20,B7:B20,T7,C7:C20,"wristband")+SUMIFS(F7:F20,B7:B20,T7,C7:C20,"sunglasses") -> 173.1 | T7: lama | U7: =IF(S7>100,"Good Customer","Normal Customer") -> Good Customer | V7: =S7/SUM(S7:S13) -> 0.25615224 | W7: =VLOOKUP(T7, database!$A$2:$B$8,2, FALSE) -> dubi
B8: lana | C8: wristband | D8: 40 | E8: 45660 | F8: =D8-(D8*H8) -> 39.2 | G8: london | H8: 0.02 | I8: =EOMONTH(MainTable[[#This Row],[Date]],2) -> 45747 | J8: =MainTable[[#This Row],[collection date]]-TODAY() -> -307 | K8: Gold | S8: =SUMIFS(F8:F21,B8:B21,T8,C8:C21,"necklace")+SUMIFS(F8:F21,B8:B21,T8,C8:C21,"ring")+SUMIFS(F8:F21,B8:B21,T8,C8:C21,"wristband")+SUMIFS(F8:F21,B8:B21,T8,C8:C21,"sunglasses") -> 179.55 | T8: mert | U8: =IF(S8>100,"Good Customer","Normal Customer") -> Good Customer | V8: =S8/SUM(S8:S14) -> 0.35719259 | W8: =VLOOKUP(T8, database!$A$2:$B$8,2, FALSE) -> egypt
B9: lama | C9: ring | D9: 150 | E9: 45661 | F9: =D9-(D9*H9) -> 139.5 | G9: dubi | H9: 0.07 | I9: =EOMONTH(MainTable[[#This Row],[Date]],2) -> 45747 | J9: =MainTable[[#This Row],[collection date]]-TODAY() -> -307 | K9: Diamond | S9: =SUMIFS(F9:F22,B9:B22,T9,C9:C22,"necklace")+SUMIFS(F9:F22,B9:B22,T9,C9:C22,"ring")+SUMIFS(F9:F22,B9:B22,T9,C9:C22,"wristband")+SUMIFS(F9:F22,B9:B22,T9,C9:C22,"sunglasses") -> 120.96 | T9: mazen | U9: =IF(S9>100,"Good Customer","Normal Customer") -> Good Customer | V9: =S9/SUM(S9:S15) -> 0.37435009 | W9: =VLOOKUP(T9, database!$A$2:$B$8,2, FALSE) -> istanbul
B10: dania | C10: sunglasses | D10: 55 | E10: 45662 | F10: =D10-(D10*H10) -> 54.45 | G10: istanbul | H10: 0.01 | I10: =EOMONTH(MainTable[[#This Row],[Date]],2) -> 45747 | J10: =MainTable[[#This Row],[collection date]]-TODAY() -> -307 | K10: Gold | S10: =SUMIFS(F10:F23,B10:B23,T10,C10:C23,"necklace")+SUMIFS(F10:F23,B10:B23,T10,C10:C23,"ring")+SUMIFS(F10:F23,B10:B23,T10,C10:C23,"wristband")+SUMIFS(F10:F23,B10:B23,T10,C10:C23,"sunglasses") -> 54.45 | T10: dania | U10: =IF(S10>100,"Good Customer","Normal Customer") -> Normal Customer | V10: =S10/SUM(S10:S16) -> 0.26934112 | W10: =VLOOKUP(T10, database!$A$2:$B$8,2, FALSE) -> istanbul
B11: mert | C11: necklace | D11: 45 | E11: 45663 | F11: =D11-(D11*H11) -> 44.55 | G11: egybt | H11: 0.01 | I11: =EOMONTH(MainTable[[#This Row],[Date]],2) -> 45747 | J11: =MainTable[[#This Row],[collection date]]-TODAY() -> -307 | K11: Gold | S11: =SUMIFS(F11:F24,B11:B24,T11,C11:C24,"necklace")+SUMIFS(F11:F24,B11:B24,T11,C11:C24,"ring")+SUMIFS(F11:F24,B11:B24,T11,C11:C24,"wristband")+SUMIFS(F11:F24,B11:B24,T11,C11:C24,"sunglasses") -> 89.51 | T11: fadel | U11: =IF(S11>100,"Good Customer","Normal Customer") -> Normal Customer | V11: =S11/SUM(S11:S17) -> 0.6059847 | W11: =VLOOKUP(T11, database!$A$2:$B$8,2, FALSE) -> london
B12: mazen | C12: sunglasses | D12: 20 | E12: 45664 | F12: =D12-(D12*H12) -> 19.76 | G12: istanbul | H12: 0.012 | I12: =EOMONTH(MainTable[[#This Row],[Date]],2) -> 45747 | J12: =MainTable[[#This Row],[collection date]]-TODAY() -> -307 | K12: Gold | S12: =SUMIFS(F12:F25,B12:B25,T12,C12:C25,"necklace")+SUMIFS(F12:F25,B12:B25,T12,C12:C25,"ring")+SUMIFS(F12:F25,B12:B25,T12,C12:C25,"wristband")+SUMIFS(F12:F25,B12:B25,T12,C12:C25,"sunglasses") -> 58.2 | T12: lana | U12: =IF(S12>100,"Good Customer","Normal Customer") -> Normal Customer | V12: =S12/SUM(S12:S18) -> 1 | W12: =VLOOKUP(T12, database!$A$2:$B$8,2, FALSE) -> london
B13: fadel | C13: sunglasses | D13: 20 | E13: 45665 | F13: =D13-(D13*H13) -> 19.76 | G13: london | H13: 0.012 | I13: =EOMONTH(MainTable[[#This Row],[Date]],2) -> 45747 | J13: =MainTable[[#This Row],[collection date]]-TODAY() -> -307 | K13: Gold
B14: rania | C14: necklace | D14: 150 | E14: 45666 | F14: =D14-(D14*H14) -> 139.5 | G14: berlin | H14: 0.07 | I14: =EOMONTH(MainTable[[#This Row],[Date]],2) -> 45747 | J14: =MainTable[[#This Row],[collection date]]-TODAY() -> -307 | K14: Diamond
B15: lana | C15: wristband | D15: 60 | E15: 45667 | F15: =D15-(D15*H15) -> 58.2 | G15: london | H15: 0.03 | I15: =EOMONTH(MainTable[[#This Row],[Date]],2) -> 45747 | J15: =MainTable[[#This Row],[collection date]]-TODAY() -> -307 | K15: Gold
B16: mert | C16: wristband | D16: 150 | E16: 45668 | F16: =D16-(D16*H16) -> 135 | G16: egypt | H16: 0.1 | I16: =EOMONTH(MainTable[[#This Row],[Date]],2) -> 45747 | J16: =MainTable[[#This Row],[collection date]]-TODAY() -> -307 | K16: Gold
B17: lama | C17: ring | D17: 35 | E17: 45669 | F17: =D17-(D17*H17) -> 33.6 | G17: dubi | H17: 0.04 | I17: =EOMONTH(MainTable[[#This Row],[Date]],2) -> 45747 | J17: =MainTable[[#This Row],[collection date]]-TODAY() -> -307 | K17: Diamond
B18: fadel | C18: necklace | D18: 75 | E18: 45670 | F18: =D18-(D18*H18) -> 69.75 | G18: london | H18: 0.07 | I18: =EOMONTH(MainTable[[#This Row],[Date]],2) -> 45747 | J18: =MainTable[[#This Row],[collection date]]-TODAY() -> -307 | K18: Diamond
B19: mazen | C19: necklace | D19: 110 | E19: 45671 | F19: =D19-(D19*H19) -> 101.2 | G19: istanbul | H19: 0.08 | I19: =EOMONTH(MainTable[[#This Row],[Date]],2) -> 45747 | J19: =MainTable[[#This Row],[collection date]]-TODAY() -> -307 | K19: Diamond
A20: Total | D20: =SUBTOTAL(109,D6:D19) -> 1060 | F20: =SUBTOTAL(109,F6:F19) -> 998.47 | H20: =SUBTOTAL(109,H6:H19) -> 0.594

Sheet sales of customers
A2: Row Labels | B2: Sum of Net profit
A3: dania | B3: 149.45
A4: mazen | B4: 120.96
A5: Grand Total | B5: 270.41

Sheet sales by customers types
A2: Row Labels | B2: Sum of Net profit
A3: Good Customer | B3: 120.96
A4: Normal Customer | B4: 149.45
A5: Grand Total | B5: 270.41

Sheet control 

Sheet sales by city
A2: Row Labels | B2: Sum of Net profit
A3: istanbul
A4: dania | B4: 149.45
A5: mazen | B5: 120.96
A6: Grand Total | B6: 270.41

Sheet sales by the jewelry
A2: Row Labels | B2: Sum of Net profit
A3: Diamond | B3: 101.2
A4: Gold | B4: 169.21
A5: Grand Total | B5: 270.41

Sheet trend by the sales
A2: Row Labels | B2: Sum of Net profit
A3: 45658 | B3: 95
A4: 45662 | B4: 54.45
A5: 45664 | B5: 19.76
A6: 45671 | B6: 101.2
A7: Grand Total | B7: 270.41

Sheet pivot tables
A1: Row Labels | B1: Sum of The price
A2: fadel
A3: necklace | B3: 75
A4: sunglasses | B4: 20
A5: Grand Total | B5: 95
A46: Row Labels | B46: Sum of Total sales | C46: Sum of percentage of sales
A47: fadel
A48: Normal Customer
A49: london | B49: 89.51 | C49: 0.6059847
A50: Grand Total | B50: 89.51 | C50: 0.6059847

Sheet database
A1: Customer | B1: City
A2: dania | B2: istanbul | E2: Type of sales | G2: Type of the jewelry
A3: lana | B3: london | E3: necklace | G3: Gold
A4: lama | B4: dubi | E4: ring | G4: Diamond
A5: mazen | B5: istanbul | E5: wristband
A6: fadel | B6: london | E6: sunglasses
A7: mert | B7: egypt
A8: rania | B8: berlin
