Workbook

Sheet Sheet1
B3: Column Labels
B4: toplam satışlar | M4: satışlar oranı | X4: Total toplam satışlar | Y4: Total satışlar oranı
B5: aksaray | C5: alanya | D5: bursa | E5: gaziosmanpaşa | F5: iğdir | G5: isparta | H5: istanbul | I5: malatya | J5: manisa | K5: siirt | L5: tekirdağ | M5: aksaray | N5: alanya | O5: bursa | P5: gaziosmanpaşa | Q5: iğdir | R5: isparta | S5: istanbul | T5: malatya | U5: manisa | V5: siirt | W5: tekirdağ
A6: Row Labels | B6: güçlü bir müşteri | C6: normal bir müşteri | D6: normal bir müşteri | E6: güçlü bir müşteri | F6: normal bir müşteri | G6: normal bir müşteri | H6: normal bir müşteri | I6: güçlü bir müşteri | J6: normal bir müşteri | K6: normal bir müşteri | L6: normal bir müşteri | M6: güçlü bir müşteri | N6: normal bir müşteri | O6: normal bir müşteri | P6: güçlü bir müşteri | Q6: normal bir müşteri | R6: normal bir müşteri | S6: normal bir müşteri | T6: güçlü bir müşteri | U6: normal bir müşteri | V6: normal bir müşteri | W6: normal bir müşteri
A7: ahmad | H7: 1720 | S7: 0.078616352 | X7: 1720 | Y7: 0.078616352
A8: dania | K8: 2365 | V8: 0.13722555 | X8: 2365 | Y8: 0.13722555
A9: esmer | C9: 0 | N9: 0 | X9: 0 | Y9: 0
A10: lana | G10: 860 | R10: 0.043215212 | X10: 860 | Y10: 0.043215212
A11: luna | E11: 4730 | P11: 0.413845 | X11: 4730 | Y11: 0.413845
A12: mohammed | I12: 3440 | T12: 0.2313476 | X12: 3440 | Y12: 0.2313476
A13: rania | D13: 1806 | O13: 0.094850949 | X13: 1806 | Y13: 0.094850949
A14: riyad | F14: -911.6 | Q14: 1 | X14: -911.6 | Y14: 1
A15: sara | L15: 258 | W15: 0.012798635 | X15: 258 | Y15: 0.012798635
A16: ümit | J16: 1591 | U16: 2.3417722 | X16: 1591 | Y16: 2.3417722
A17: yaser | B17: 6020 | M17: 0.89858793 | X17: 6020 | Y17: 0.89858793
A18: Grand Total | B18: 6020 | C18: 0 | D18: 1806 | E18: 4730 | F18: -911.6 | G18: 860 | H18: 1720 | I18: 3440 | J18: 1591 | K18: 2365 | L18: 258 | M18: 0.89858793 | N18: 0 | O18: 0.094850949 | P18: 0.413845 | Q18: 1 | R18: 0.043215212 | S18: 0.078616352 | T18: 0.2313476 | U18: 2.3417722 | V18: 0.13722555 | W18: 0.012798635 | X18: 21878.4 | Y18: 5.2522594
A26: Row Labels | B26: Sum of fatura | C26: Sum of vergi | D26: Sum of net karı
A27: ahmad | B27: 8000 | C27: 1120 | D27: 6880
A28: dönüş | B28: 3000 | C28: 420 | D28: 2580
A29: May | B29: 3000 | C29: 420 | D29: 2580
A30: fatura | B30: 5000 | C30: 700 | D30: 4300
A31: May | B31: 5000 | C31: 700 | D31: 4300
A32: baraa | B32: 800 | C32: 112 | D32: 688
A33: dönüş | B33: 800 | C33: 112 | D33: 688
A34: Haz | B34: 800 | C34: 112 | D34: 688
A35: dania | B35: 2750 | C35: 385 | D35: 1591
A36: fatura | B36: 2300 | C36: 322 | D36: 1978
A37: May | B37: 2300 | C37: 322 | D37: 1978
A38: indrim | B38: 450 | C38: 63 | D38: -387
... A88: Grand Total | B88: 49010 | C88: 6861.4 | D88: 30968.6

Sheet pivot table
A3: Row Labels | B3: Sum of net karı | C3: Sum of vergi | D3: Sum of fatura
A4: dönüş
A5: ahmad | B5: 2580 | C5: 420 | D5: 3000
A6: baraa | B6: 688 | C6: 112 | D6: 800
A7: esmer | B7: 0 | C7: 280 | D7: 2000
A8: muammer | B8: 1720 | C8: 280 | D8: 2000
A9: rania | B9: 774 | C9: 126 | D9: 900
A10: fatura
A11: ahmad | B11: 4300 | C11: 700 | D11: 5000
A12: dania | B12: 1978 | C12: 322 | D12: 2300
A13: lana | B13: 860 | C13: 140 | D13: 1000
A14: luna | B14: 5160 | C14: 840 | D14: 6000
A15: majed | B15: -2064 | C15: 336 | D15: 2400
A16: mohammed | B16: 3440 | C16: 560 | D16: 4000
A17: rania | B17: 2580 | C17: 420 | D17: 3000
A18: sara | B18: 258 | C18: 686 | D18: 4900
A19: ümit | B19: 1290 | C19: 210 | D19: 1500
A20: yaser | B20: 6020 | C20: 980 | D20: 7000
A21: indrim
A22: dania | B22: -387 | C22: 63 | D22: 450
A23: khaled | B23: 473 | C23: 77 | D23: 550
A24: luna | B24: 430 | C24: 70 | D24: 500
A25: riyad | B25: 911.6 | C25: 148.4 | D25: 1060
A26: ümit | B26: -301 | C26: 49 | D26: 350
A27: yousra | B27: 258 | C27: 42 | D27: 300
A28: Grand Total | B28: 30968.6 | C28: 6861.4 | D28: 49010
A74: Row Labels | B74: Sum of toplam satışlar | C74: Sum of satışlar oranı
A75: ahmad
A76: normal bir müşteri
A77: istanbul | B77: 1720 | C77: 0.078616352
A78: dania
A79: normal bir müşteri
A80: siirt | B80: 2365 | C80: 0.13722555
A81: esmer
A82: normal bir müşteri
A83: alanya | B83: 0 | C83: 0
A84: lana
A85: normal bir müşteri
A86: isparta | B86: 860 | C86: 0.043215212
A87: luna
...

Sheet Sayfa1
G6: MÜŞTERİLERİN VERİLERİ | P6: MÜŞTERİ ESTETİĞİ
C8: açıklama | D8: tarih | G8: müşteri adi | H8: açıklama | I8: fatura | J8: vergi | K8: net karı | L8: bölge | M8: tarih | P8: müşteri adi | Q8: toplam satışlar | R8: müşteri tipi | S8: satışlar oranı | T8: bölge
C9: fatura | D9: >=14.05.2020 | G9: ahmad | H9: fatura | I9: 5000 | J9: =I9*0.14 -> 700 | K9: =I9-J9 -> 4300 | L9: istanbul | M9: 43965 | P9: ahmad | Q9: =SUMIFS(K9:K35,G9:G35,P9,H9:H35,"fatura")-SUMIFS(K9:K35,G9:G35,P9,H9:H35,"dönüş")-SUMIFS(K9:K35,G9:G35,P9,H9:H35,"indrim") -> 1720 | R9: =IF(Q9>10000,"önemli bir müşteri",IF(Q9>3000,"güçlü bir müşteri","normal bir müşteri")) -> normal bir müşteri | S9: =Q9/SUM(Q9:Q19) -> 0.078616352 | T9: =VLOOKUP(P9,database!B6:C16,2,FALSE) -> istanbul
G10: sara | H10: fatura | I10: 2000 | J10: =I10*0.14 -> 280 | K10: =I10-J10 -> 1720 | L10: tekirdağ | M10: 43966 | P10: sara | Q10: =SUMIFS(K10:K37,G10:G37,P10,H10:H37,"fatura")-SUMIFS(K10:K37,G10:G37,P10,H10:H37,"dönüş")-SUMIFS(K10:K37,G10:G37,P10,H10:H37,"indrim") -> 258 | R10: =IF(Q10>10000,"önemli bir müşteri",IF(Q10>3000,"güçlü bir müşteri","normal bir müşteri")) -> normal bir müşteri | S10: =Q10/SUM(Q10:Q20) -> 0.012798635 | T10: =VLOOKUP(P10,database!B7:C17,2,FALSE) -> tekirdağ
G11: lana | H11: fatura | I11: 1000 | J11: =I11*0.14 -> 140 | K11: =I11-J11 -> 860 | L11: isparta | M11: 43967 | P11: lana | Q11: =SUMIFS(K11:K38,G11:G38,P11,H11:H38,"fatura")-SUMIFS(K11:K38,G11:G38,P11,H11:H38,"dönüş")-SUMIFS(K11:K38,G11:G38,P11,H11:H38,"indrim") -> 860 | R11: =IF(Q11>10000,"önemli bir müşteri",IF(Q11>3000,"güçlü bir müşteri","normal bir müşteri")) -> normal bir müşteri | S11: =Q11/SUM(Q11:Q21) -> 0.043215212 | T11: =VLOOKUP(P11,database!B8:C18,2,FALSE) -> isparta
G12: rania | H12: fatura | I12: 3000 | J12: =I12*0.14 -> 420 | K12: =I12-J12 -> 2580 | L12: bursa | M12: 43968 | P12: rania | Q12: =SUMIFS(K12:K39,G12:G39,P12,H12:H39,"fatura")-SUMIFS(K12:K39,G12:G39,P12,H12:H39,"dönüş")-SUMIFS(K12:K39,G12:G39,P12,H12:H39,"indrim") -> 1806 | R12: =IF(Q12>10000,"önemli bir müşteri",IF(Q12>3000,"güçlü bir müşteri","normal bir müşteri")) -> normal bir müşteri | S12: =Q12/SUM(Q12:Q22) -> 0.094850949 | T12: =VLOOKUP(P12,database!B9:C19,2,FALSE) -> bursa
G13: dania | H13: fatura | I13: 300 | J13: =I13*0.14 -> 42 | K13: =I13-J13 -> 258 | L13: siirt | M13: 43969 | P13: dania | Q13: =SUMIFS(K13:K40,G13:G40,P13,H13:H40,"fatura")-SUMIFS(K13:K40,G13:G40,P13,H13:H40,"dönüş")-SUMIFS(K13:K40,G13:G40,P13,H13:H40,"indrim") -> 2365 | R13: =IF(Q13>10000,"önemli bir müşteri",IF(Q13>3000,"güçlü bir müşteri","normal bir müşteri")) -> normal bir müşteri | S13: =Q13/SUM(Q13:Q23) -> 0.13722555 | T13: =VLOOKUP(P13,database!B10:C20,2,FALSE) -> siirt
G14: mohammed | H14: fatura | I14: 4000 | J14: =I14*0.14 -> 560 | K14: =I14-J14 -> 3440 | L14: malatya | M14: 43970 | P14: mohammed | Q14: =SUMIFS(K14:K41,G14:G41,P14,H14:H41,"fatura")-SUMIFS(K14:K41,G14:G41,P14,H14:H41,"dönüş")-SUMIFS(K14:K41,G14:G41,P14,H14:H41,"indrim") -> 3440 | R14: =IF(Q14>10000,"önemli bir müşteri",IF(Q14>3000,"güçlü bir müşteri","normal bir müşteri")) -> güçlü bir müşteri | S14: =Q14/SUM(Q14:Q24) -> 0.2313476 | T14: =VLOOKUP(P14,database!B11:C21,2,FALSE) -> malatya
G15: ahmad | H15: dönüş | I15: 500 | J15: =I15*0.14 -> 70 | K15: =I15-J15 -> 430 | L15: istanbul | M15: 43971 | P15: luna | Q15: =SUMIFS(K15:K42,G15:G42,P15,H15:H42,"fatura")-SUMIFS(K15:K42,G15:G42,P15,H15:H42,"dönüş")-SUMIFS(K15:K42,G15:G42,P15,H15:H42,"indrim") -> 4730 | R15: =IF(Q15>10000,"önemli bir müşteri",IF(Q15>3000,"güçlü bir müşteri","normal bir müşteri")) -> güçlü bir müşteri | S15: =Q15/SUM(Q15:Q25) -> 0.413845 | T15: =VLOOKUP(P15,database!B12:C22,2,FALSE) -> gaziosmanpaşa
G16: sara | H16: fatura | I16: 600 | J16: =I16*0.14 -> 84 | K16: =I16-J16 -> 516 | L16: tekirdağ | M16: 43972 | P16: yaser | Q16: =SUMIFS(K16:K43,G16:G43,P16,H16:H43,"fatura")-SUMIFS(K16:K43,G16:G43,P16,H16:H43,"dönüş")-SUMIFS(K16:K43,G16:G43,P16,H16:H43,"indrim") -> 6020 | R16: =IF(Q16>10000,"önemli bir müşteri",IF(Q16>3000,"güçlü bir müşteri","normal bir müşteri")) -> güçlü bir müşteri | S16: =Q16/SUM(Q16:Q26) -> 0.89858793 | T16: =VLOOKUP(P16,database!B13:C23,2,FALSE) -> aksaray
G17: dania | H17: fatura | I17: 2000 | J17: =I17*0.14 -> 280 | K17: =I17-J17 -> 1720 | L17: siirt | M17: 43973 | P17: ümit | Q17: =SUMIFS(K17:K44,G17:G44,P17,H17:H44,"fatura")-SUMIFS(K17:K44,G17:G44,P17,H17:H44,"dönüş")-SUMIFS(K17:K44,G17:G44,P17,H17:H44,"indrim") -> 1591 | R17: =IF(Q17>10000,"önemli bir müşteri",IF(Q17>3000,"güçlü bir müşteri","normal bir müşteri")) -> normal bir müşteri | S17: =Q17/SUM(Q17:Q27) -> 2.3417722 | T17: =VLOOKUP(P17,database!B14:C24,2,FALSE) -> manisa
G18: luna | H18: fatura | I18: 6000 | J18: =I18*0.14 -> 840 | K18: =I18-J18 -> 5160 | L18: gaziosmanpaşa | M18: 43974 | P18: esmer | Q18: =SUMIFS(K18:K45,G18:G45,P18,H18:H45,"fatura")-SUMIFS(K18:K45,G18:G45,P18,H18:H45,"dönüş")-SUMIFS(K18:K45,G18:G45,P18,H18:H45,"indrim") -> 0 | R18: =IF(Q18>10000,"önemli bir müşteri",IF(Q18>3000,"güçlü bir müşteri","normal bir müşteri")) -> normal bir müşteri | S18: =Q18/SUM(Q18:Q28) -> 0 | T18: =VLOOKUP(P18,database!B15:C25,2,FALSE) -> alanya
G19: yaser | H19: fatura | I19: 7000 | J19: =I19*0.14 -> 980 | K19: =I19-J19 -> 6020 | L19: aksaray | M19: 43975 | P19: riyad | Q19: =SUMIFS(K19:K46,G19:G46,P19,H19:H46,"fatura")-SUMIFS(K19:K46,G19:G46,P19,H19:H46,"dönüş")-SUMIFS(K19:K46,G19:G46,P19,H19:H46,"indrim") -> -911.6 | R19: =IF(Q19>10000,"önemli bir müşteri",IF(Q19>3000,"güçlü bir müşteri","normal bir müşteri")) -> normal bir müşteri | S19: =Q19/SUM(Q19:Q29) -> 1 | T19: =VLOOKUP(P19,database!B16:C26,2,FALSE) -> iğdir
G20: ümit | H20: fatura | I20: 1500 | J20: =I20*0.14 -> 210 | K20: =I20-J20 -> 1290 | L20: manisa | M20: 43976
G21: esmer | H21: dönüş | I21: 1000 | J21: =I21*0.14 -> 140 | K21: =I21-J21 -> 860 | L21: alanya | M21: 43977
G22: luna | H22: indrim | I22: 500 | J22: =I22*0.14 -> 70 | K22: =I22-J22 -> 430 | L22: gaziosmanpaşa | M22: 43978
G23: riyad | H23: indrim | I23: 400 | J23: =I23*0.14 -> 56 | K23: =I23-J23 -> 344 | L23: iğdir | M23: 43979
G24: muammer | H24: dönüş | I24: 2000 | J24: =I24*0.14 -> 280 | K24: =I24-J24 -> 1720 | L24: balıkesir | M24: 43980
G25: ahmad | H25: dönüş | I25: 2500 | J25: =I25*0.14 -> 350 | K25: =I25-J25 -> 2150 | L25: istanbul | M25: 43981
G26: yousra | H26: indrim | I26: 300 | J26: =I26*0.14 -> 42 | K26: =I26-J26 -> 258 | L26: sakarya | M26: 43982
G27: riyad | H27: indrim | I27: 660 | J27: =I27*0.14 -> 92.4 | K27: =I27-J27 -> 567.6 | L27: samsun | M27: 43983
G28: khaled | H28: indrim | I28: 550 | J28: =I28*0.14 -> 77 | K28: =I28-J28 -> 473 | L28: trabzon | M28: 43984
G29: baraa | H29: dönüş | I29: 800 | J29: =I29*0.14 -> 112 | K29: =I29-J29 -> 688 | L29: gaziantep | M29: 43985
G30: rania | H30: dönüş | I30: 900 | J30: =I30*0.14 -> 126 | K30: =I30-J30 -> 774 | L30: bursa | M30: 43986
G31: esmer | H31: dönüş | I31: 1000 | J31: =I31*0.14 -> 140 | K31: =-(I31-J31) -> -860 | L31: alanya | M31: 43987
G32: dania | H32: indrim | I32: 450 | J32: =I32*0.14 -> 63 | K32: =-(I32-J32) -> -387 | L32: siirt | M32: 43988
G33: ümit | H33: indrim | I33: 350 | J33: =I33*0.14 -> 49 | K33: =-(I33-J33) -> -301 | L33: manisa | M33: 43989
G34: sara | H34: fatura | I34: 2300 | J34: =I34*0.14 -> 322 | K34: =-(I34-J34) -> -1978 | L34: tekirdağ | M34: 43990
G35: majed | H35: fatura | I35: 2400 | J35: =I35*0.14 -> 336 | K35: =-(I35-J35) -> -2064 | L35: adana | M35: 43991
F36: toplam | G36: Total | M36: =SUBTOTAL(103,AnaTablo[tarih]) -> 27
G37: =COUNTA(G9:G35) -> 27 | I37: =SUMIFS(I9:I35, H9:H35,"fatura", L9:L35,"adana") -> 2400 | K37: =SUBTOTAL(109,K9:K35) -> 30968.6

Sheet Advanced Filter
B4: net karı | C4: bölge | G4: müşteri adi | H4: açıklama | I4: fatura | J4: vergi | K4: net karı | L4: bölge | M4: tarih | P4: müşteri adi | Q4: açıklama
B5: 4300 | C5: istanbul | G5: ahmad | H5: fatura | I5: 5000 | J5: 700 | K5: 4300 | L5: istanbul | M5: 43965 | P5: ahmad | Q5: fatura
B6: 1720 | C6: tekirdağ | G6: sara | H6: fatura | I6: 2000 | J6: 280 | K6: 1720 | L6: tekirdağ | M6: 43966 | P6: sara | Q6: fatura
B7: 860 | C7: isparta | G7: lana | H7: fatura | I7: 1000 | J7: 140 | K7: 860 | L7: isparta | M7: 43967 | P7: lana | Q7: fatura
B8: 2580 | C8: bursa | G8: rania | H8: fatura | I8: 3000 | J8: 420 | K8: 2580 | L8: bursa | M8: 43968 | P8: rania | Q8: fatura
B9: 258 | C9: siirt | G9: dania | H9: fatura | I9: 300 | J9: 42 | K9: 258 | L9: siirt | M9: 43969 | P9: dania | Q9: fatura
B10: 3440 | C10: malatya | G10: mohammed | H10: fatura | I10: 4000 | J10: 560 | K10: 3440 | L10: malatya | M10: 43970 | P10: mohammed | Q10: fatura
B11: 516 | C11: tekirdağ | G11: sara | H11: fatura | I11: 600 | J11: 84 | K11: 516 | L11: tekirdağ | M11: 43972 | P11: sara | Q11: fatura
B12: 1720 | C12: siirt | G12: dania | H12: fatura | I12: 2000 | J12: 280 | K12: 1720 | L12: siirt | M12: 43973 | P12: dania | Q12: fatura
B13: 5160 | C13: gaziosmanpaşa | G13: luna | H13: fatura | I13: 6000 | J13: 840 | K13: 5160 | L13: gaziosmanpaşa | M13: 43974 | P13: luna | Q13: fatura
B14: 6020 | C14: aksaray | G14: yaser | H14: fatura | I14: 7000 | J14: 980 | K14: 6020 | L14: aksaray | M14: 43975 | P14: yaser | Q14: fatura
B15: 1290 | C15: manisa | G15: ümit | H15: fatura | I15: 1500 | J15: 210 | K15: 1290 | L15: manisa | M15: 43976 | P15: ümit | Q15: fatura
B16: -1978 | C16: tekirdağ | G16: sara | H16: fatura | I16: 2300 | J16: 322 | K16: -1978 | L16: tekirdağ | M16: 43990 | P16: sara | Q16: fatura
B17: -2064 | C17: adana | G17: majed | H17: fatura | I17: 2400 | J17: 336 | K17: -2064 | L17: adana | M17: 43991 | P17: majed | Q17: fatura

Sheet database
B5: müşteri adi | C5: bölge
B6: ahmad | C6: istanbul
B7: sara | C7: tekirdağ
B8: lana | C8: isparta
B9: rania | C9: bursa
B10: dania | C10: siirt
B11: mohammed | C11: malatya
B12: luna | C12: gaziosmanpaşa
B13: yaser | C13: aksaray
B14: ümit | C14: manisa
B15: esmer | C15: alanya
B16: riyad | C16: iğdir
